<?xml version="1.0" ?>
<robot name="iCub">
  <joint name="l_hip_pitch" type="revolute">
    <parent link="root_link"/>
    <child link="l_hip_1"/>
    <origin rpy="0       1.57079 -1.57079" xyz="-1.2879  0.671   0.4971"/>
    <axis xyz="0 -1  0"/>
    <limit effort="84.0" lower="-0.767945" upper="2.30383" velocity="100.0"/>
  </joint>
  <joint name="l_hip_roll" type="revolute">
    <parent link="l_hip_1"/>
    <child link="l_hip_2"/>
    <origin rpy="1.20394 -1.57079  1.93764" xyz="0 0 0"/>
    <axis xyz="1 0 0"/>
    <limit effort="84.0" lower="-2.07694" upper="0.296706" velocity="100.0"/>
  </joint>
  <joint name="l_leg_ft_sensor" type="fixed">
    <parent link="l_hip_2"/>
    <child link="l_hip_3"/>
    <origin rpy="0 0 0" xyz="0     0     0.0665"/>
    <axis xyz="0 0 0"/>
    <limit effort="0.0" lower="0.0" upper="0.0" velocity="0.0"/>
  </joint>
  <joint name="l_hip_yaw" type="revolute">
    <parent link="l_hip_3"/>
    <child link="l_upper_leg"/>
    <origin rpy="-1.5708  0      0" xyz="0      0     -0.0665"/>
    <axis xyz="0 1 0"/>
    <limit effort="40.0" lower="-1.37881" upper="1.37881" velocity="100.0"/>
  </joint>
  <joint name="l_knee" type="revolute">
    <parent link="l_upper_leg"/>
    <child link="l_lower_leg"/>
    <origin rpy="3.14159 0      1.5708" xyz="0     -0.2236  0"/>
    <axis xyz="0  0 -1"/>
    <limit effort="30.0" lower="-2.18166" upper="0.401426" velocity="100.0"/>
  </joint>
  <joint name="l_ankle_pitch" type="revolute">
    <parent link="l_lower_leg"/>
    <child link="l_ankle_1"/>
    <origin rpy="-1.5708  0      0" xyz="-0.213  0     0"/>
    <axis xyz="0 -1  0"/>
    <limit effort="24.0" lower="-0.733038" upper="0.366519" velocity="100.0"/>
  </joint>
  <joint name="l_ankle_roll" type="revolute">
    <parent link="l_ankle_1"/>
    <child link="l_ankle_2"/>
    <origin rpy="-2.64933 -1.57078  2.64933" xyz="0 0 0"/>
    <axis xyz="1 0 0"/>
    <limit effort="11.0" lower="-0.418879" upper="0.418879" velocity="100.0"/>
  </joint>
  <joint name="l_foot_ft_sensor" type="fixed">
    <parent link="l_ankle_2"/>
    <child link="l_foot"/>
    <origin rpy="0 0 0" xyz="0    0    0.037"/>
    <axis xyz="0 0 0"/>
    <limit effort="0.0" lower="0.0" upper="0.0" velocity="0.0"/>
  </joint>
  <joint name="r_hip_pitch" type="revolute">
    <parent link="root_link"/>
    <child link="r_hip_1"/>
    <origin rpy="3.14159  1.57079 -1.57079" xyz="-1.4241  0.671   0.4971"/>
    <axis xyz="0 1 0"/>
    <limit effort="84.0" lower="-0.767945" upper="2.30383" velocity="100.0"/>
  </joint>
  <joint name="r_hip_roll" type="revolute">
    <parent link="r_hip_1"/>
    <child link="r_hip_2"/>
    <origin rpy="1.93764 1.57079 1.93764" xyz="0 0 0"/>
    <axis xyz="-1  0  0"/>
    <limit effort="84.0" lower="-2.07694" upper="0.296706" velocity="100.0"/>
  </joint>
  <joint name="r_leg_ft_sensor" type="fixed">
    <parent link="r_hip_2"/>
    <child link="r_hip_3"/>
    <origin rpy="0 0 0" xyz="0     0     0.0665"/>
    <axis xyz="0 0 0"/>
    <limit effort="0.0" lower="0.0" upper="0.0" velocity="0.0"/>
  </joint>
  <joint name="r_hip_yaw" type="revolute">
    <parent link="r_hip_3"/>
    <child link="r_upper_leg"/>
    <origin rpy="-1.5708  0      0" xyz="0      0     -0.0665"/>
    <axis xyz="0 -1  0"/>
    <limit effort="40.0" lower="-1.37881" upper="1.37881" velocity="100.0"/>
  </joint>
  <joint name="r_knee" type="revolute">
    <parent link="r_upper_leg"/>
    <child link="r_lower_leg"/>
    <origin rpy="3.14158 0      1.5708" xyz="0     -0.2236  0"/>
    <axis xyz="0  0 -1"/>
    <limit effort="30.0" lower="-2.18166" upper="0.401426" velocity="100.0"/>
  </joint>
  <joint name="r_ankle_pitch" type="revolute">
    <parent link="r_lower_leg"/>
    <child link="r_ankle_1"/>
    <origin rpy="1.5708 0     0" xyz="-0.213  0     0"/>
    <axis xyz="0 1 0"/>
    <limit effort="24.0" lower="-0.733038" upper="0.366519" velocity="100.0"/>
  </joint>
  <joint name="r_ankle_roll" type="revolute">
    <parent link="r_ankle_1"/>
    <child link="r_ankle_2"/>
    <origin rpy="-0.67357  1.57079  2.46801" xyz="0 0 0"/>
    <axis xyz="-1  0  0"/>
    <limit effort="11.0" lower="-0.418879" upper="0.418879" velocity="100.0"/>
  </joint>
  <joint name="r_foot_ft_sensor" type="fixed">
    <parent link="r_ankle_2"/>
    <child link="r_foot"/>
    <origin rpy="0 0 0" xyz="0    0    0.037"/>
    <axis xyz="0 0 0"/>
    <limit effort="0.0" lower="0.0" upper="0.0" velocity="0.0"/>
  </joint>
  <joint name="torso_pitch" type="revolute">
    <parent link="root_link"/>
    <child link="torso_1"/>
    <origin rpy="3.14159 -1.57079  1.57079" xyz="-1.356  0.671  0.617"/>
    <axis xyz="0 1 0"/>
    <limit effort="36.0" lower="-0.383972" upper="1.46608" velocity="100.0"/>
  </joint>
  <joint name="torso_roll" type="revolute">
    <parent link="torso_1"/>
    <child link="torso_2"/>
    <origin rpy="1.57079  0      -1.5708" xyz="0.032 0    0"/>
    <axis xyz="0 1 0"/>
    <limit effort="80.0" lower="-0.680678" upper="0.680678" velocity="100.0"/>
  </joint>
  <joint name="torso_yaw" type="revolute">
    <parent link="torso_2"/>
    <child link="chest"/>
    <origin rpy="-1.57079  0      -1.5708" xyz="0     -0.0055  0"/>
    <axis xyz="0 -1  0"/>
    <limit effort="80.0" lower="-1.02974" upper="1.02974" velocity="100.0"/>
  </joint>
  <joint name="l_shoulder_pitch" type="revolute">
    <parent link="chest"/>
    <child link="l_shoulder_1"/>
    <origin rpy="1.30899 0      1.57079" xyz="0.00525  0.1433  -0.11026"/>
    <axis xyz="0 -1  0"/>
    <limit effort="84.0" lower="-1.65806" upper="0.0872665" velocity="100.0"/>
  </joint>
  <joint name="l_shoulder_roll" type="revolute">
    <parent link="l_shoulder_1"/>
    <child link="l_shoulder_2"/>
    <origin rpy="1.5708   0      -1.57079" xyz="0 0 0"/>
    <axis xyz="0 1 0"/>
    <limit effort="84.0" lower="0.0" upper="2.80649" velocity="100.0"/>
  </joint>
  <joint name="l_shoulder_yaw" type="revolute">
    <parent link="l_shoulder_2"/>
    <child link="l_shoulder_3"/>
    <origin rpy="0    0    1.309" xyz="0 0 0"/>
    <axis xyz="0 0 1"/>
    <limit effort="34.0" lower="-0.645772" upper="1.74533" velocity="100.0"/>
  </joint>
  <joint name="l_arm_ft_sensor" type="fixed">
    <parent link="l_shoulder_3"/>
    <child link="l_upper_arm"/>
    <origin rpy="0 0 0" xyz="0.015 0    0.068"/>
    <axis xyz="0 0 0"/>
    <limit effort="0.0" lower="0.0" upper="0.0" velocity="0.0"/>
  </joint>
  <joint name="l_elbow" type="revolute">
    <parent link="l_upper_arm"/>
    <child link="l_elbow_1"/>
    <origin rpy="0 0 0" xyz="0      0      0.08428"/>
    <axis xyz="0 1 0"/>
    <limit effort="20.0" lower="0.0959931" upper="1.85005" velocity="100.0"/>
  </joint>
  <joint name="l_wrist_prosup" type="revolute">
    <parent link="l_elbow_1"/>
    <child link="l_forearm"/>
    <origin rpy="1.57079  0      -1.5708" xyz="-0.015  0     0"/>
    <axis xyz="0 1 0"/>
    <limit effort="0.45" lower="-0.872665" upper="0.872665" velocity="100.0"/>
  </joint>
  <joint name="l_wrist_pitch" type="revolute">
    <parent link="l_forearm"/>
    <child link="l_wrist_1"/>
    <origin rpy="1.5708  0      1.57079" xyz="0     0.1373 0"/>
    <axis xyz="0 1 0"/>
    <limit effort="0.65" lower="-1.13446" upper="0.174533" velocity="100.0"/>
  </joint>
  <joint name="l_wrist_yaw" type="revolute">
    <parent link="l_wrist_1"/>
    <child link="l_hand"/>
    <origin rpy="0 0 0" xyz="0 0 0"/>
    <axis xyz="0 0 1"/>
    <limit effort="0.65" lower="-0.436332" upper="0.436332" velocity="100.0"/>
  </joint>
  <joint name="neck_pitch" type="revolute">
    <parent link="chest"/>
    <child link="neck_1"/>
    <origin rpy="1.57079 0      1.57079" xyz="0.00231 0.1933  0"/>
    <axis xyz="0 1 0"/>
    <limit effort="-1.0" lower="-0.698132" upper="0.523599" velocity="0.0"/>
  </joint>
  <joint name="neck_roll" type="revolute">
    <parent link="neck_1"/>
    <child link="neck_2"/>
    <origin rpy="-1.5708  0     -1.5708" xyz="0.0095 0     0"/>
    <axis xyz="0 -1  0"/>
    <limit effort="-1.0" lower="-1.22173" upper="1.0472" velocity="0.0"/>
  </joint>
  <joint name="neck_yaw" type="revolute">
    <parent link="neck_2"/>
    <child link="head"/>
    <origin rpy="-1.5708   0       1.57079" xyz="0 0 0"/>
    <axis xyz="0 -1  0"/>
    <limit effort="-1.0" lower="-0.959931" upper="0.959931" velocity="0.0"/>
  </joint>
  <joint name="eye_tilt" type="revolute">
    <parent link="head"/>
    <child link="eye_frame"/>
    <origin rpy="0 0 0" xyz="-0.04859 -0.11204  0"/>
    <axis xyz="0 0 1"/>
    <limit effort="-1.0" lower="-0.942477796" upper="0.942477796" velocity="0.0"/>
  </joint>
  <joint name="left_eye_pan" type="revolute">
    <parent link="eye_frame"/>
    <child link="left_eye"/>
    <origin rpy="0 0 0" xyz="0     0    -0.034"/>
    <axis xyz="0 -1  0"/>
    <limit effort="-1.0" lower="-0.942477796" upper="0.942477796" velocity="0.0"/>
  </joint>
  <joint name="right_eye_pan" type="revolute">
    <parent link="eye_frame"/>
    <child link="right_eye"/>
    <origin rpy="0 0 0" xyz="0    0    0.034"/>
    <axis xyz="0 -1  0"/>
    <limit effort="-1.0" lower="-0.942477796" upper="0.942477796" velocity="0.0"/>
  </joint>
  <joint name="r_shoulder_pitch" type="revolute">
    <parent link="chest"/>
    <child link="r_shoulder_1"/>
    <origin rpy="-1.30899  0       1.57079" xyz="0.00525 0.1433  0.11025"/>
    <axis xyz="0 1 0"/>
    <limit effort="84.0" lower="-1.65806" upper="0.0872665" velocity="100.0"/>
  </joint>
  <joint name="r_shoulder_roll" type="revolute">
    <parent link="r_shoulder_1"/>
    <child link="r_shoulder_2"/>
    <origin rpy="-1.57079  0      -1.57079" xyz="0 0 0"/>
    <axis xyz="0 -1  0"/>
    <limit effort="84.0" lower="0.0" upper="2.80649" velocity="100.0"/>
  </joint>
  <joint name="r_shoulder_yaw" type="revolute">
    <parent link="r_shoulder_2"/>
    <child link="r_shoulder_3"/>
    <origin rpy="3.14158 0      1.309" xyz="0 0 0"/>
    <axis xyz="0  0 -1"/>
    <limit effort="34.0" lower="-0.645772" upper="1.74533" velocity="100.0"/>
  </joint>
  <joint name="r_arm_ft_sensor" type="fixed">
    <parent link="r_shoulder_3"/>
    <child link="r_upper_arm"/>
    <origin rpy="0 0 0" xyz="0.015 0    0.068"/>
    <axis xyz="0 0 0"/>
    <limit effort="0.0" lower="0.0" upper="0.0" velocity="0.0"/>
  </joint>
  <joint name="r_elbow" type="revolute">
    <parent link="r_upper_arm"/>
    <child link="r_elbow_1"/>
    <origin rpy="3.14158 0      3.14159" xyz="0      0      0.08428"/>
    <axis xyz="0 1 0"/>
    <limit effort="20.0" lower="0.0959931" upper="1.85005" velocity="100.0"/>
  </joint>
  <joint name="r_wrist_prosup" type="revolute">
    <parent link="r_elbow_1"/>
    <child link="r_forearm"/>
    <origin rpy="1.57079  0      -1.5708" xyz="0.015 0    0"/>
    <axis xyz="0 1 0"/>
    <limit effort="0.45" lower="-0.872665" upper="0.872665" velocity="100.0"/>
  </joint>
  <joint name="r_wrist_pitch" type="revolute">
    <parent link="r_forearm"/>
    <child link="r_wrist_1"/>
    <origin rpy="1.5708  0      1.57079" xyz="0     -0.1373  0"/>
    <axis xyz="0 1 0"/>
    <limit effort="0.65" lower="-1.13446" upper="0.174533" velocity="100.0"/>
  </joint>
  <joint name="r_wrist_yaw" type="revolute">
    <parent link="r_wrist_1"/>
    <child link="r_hand"/>
    <origin rpy="0      0      3.14159" xyz="0 0 0"/>
    <axis xyz="0 0 1"/>
    <limit effort="0.65" lower="-0.436332" upper="0.436332" velocity="100.0"/>
  </joint>
  <link name="root_link">
    <inertial>
      <mass value="4.72"/>
      <origin rpy="0 0 0" xyz="0 0 0"/>
      <inertia ixx="0.01" ixy="0" ixz="0" iyy="0.01" iyz="0" izz="0.01"/>
    </inertial>
    <collision name="root_link_collision">
      <origin rpy="0      0      1.57079" xyz="-1.356  0.671  0.617"/>
      <geometry>
        <mesh filename="package://demonstrator6_description/meshes/collision/icub_simple_collision_root_link.dae" scale="1 1 1"/>
      </geometry>
    </collision>
    <visual name="root_link_visual">
      <origin rpy="0      0      1.57079" xyz="-1.356  0.671  0.617"/>
      <geometry>
        <mesh filename="package://demonstrator6_description/meshes/visual/icub_root_link.dae" scale="1 1 1"/>
      </geometry>
    </visual>
  </link>
  <link name="l_hip_1">
    <inertial>
      <mass value="0.754"/>
      <origin rpy="0 0 0" xyz="0     -0.0782  0"/>
      <inertia ixx="0.01" ixy="2.059e-06" ixz="1.451e-06" iyy="0.01" iyz="1.545e-06" izz="0.01"/>
    </inertial>
    <collision name="l_hip_1_collision">
      <origin rpy="-0.7854   1.57079 -2.35618" xyz="0 0 0"/>
      <geometry>
        <mesh filename="package://demonstrator6_description/meshes/collision/icub_simple_collision_l_hip_1.dae" scale="1 1 1"/>
      </geometry>
    </collision>
    <visual name="l_hip_1_visual">
      <origin rpy="-0.7854   1.57079 -2.35618" xyz="0 0 0"/>
      <geometry>
        <mesh filename="package://demonstrator6_description/meshes/visual/icub_l_hip_1.dae" scale="1 1 1"/>
      </geometry>
    </visual>
  </link>
  <link name="l_hip_2">
    <inertial>
      <mass value="0.526"/>
      <origin rpy="0 0 0" xyz="0      0      0.03045"/>
      <inertia ixx="0.01" ixy="-7.4e-08" ixz="1.0835e-05" iyy="0.01" iyz="-6.2e-08" izz="0.01"/>
    </inertial>
    <collision name="l_hip_2_collision">
      <origin rpy="0.78536 -1.57079  2.35623" xyz="0 0 0"/>
      <geometry>
        <mesh filename="package://demonstrator6_description/meshes/collision/icub_simple_collision_l_hip_2.dae" scale="1 1 1"/>
      </geometry>
    </collision>
    <visual name="l_hip_2_visual">
      <origin rpy="0.78536 -1.57079  2.35623" xyz="0 0 0"/>
      <geometry>
        <mesh filename="package://demonstrator6_description/meshes/visual/icub_l_hip_2.dae" scale="1 1 1"/>
      </geometry>
    </visual>
  </link>
  <link name="l_hip_3">
    <inertial>
      <mass value="0.1"/>
      <origin rpy="0 0 0" xyz="0 0 0"/>
      <inertia ixx="0.01" ixy="0" ixz="0" iyy="0.01" iyz="0" izz="0.01"/>
    </inertial>
  </link>
  <link name="l_upper_leg">
    <inertial>
      <mass value="20.175"/>
      <origin rpy="0 0 0" xyz="0.00144 -0.15942 -0.00039"/>
      <inertia ixx="100.01" ixy="-6.726e-05" ixz="2.267e-06" iyy="100.01" iyz="3.63726e-05" izz="100.01"/>
    </inertial>
    <collision name="l_upper_leg_collision">
      <origin rpy="-2.67797  1.57079 -1.10715" xyz="0 0 0"/>
      <geometry>
        <mesh filename="package://demonstrator6_description/meshes/collision/icub_simple_collision_l_thigh.dae" scale="1 1 1"/>
      </geometry>
    </collision>
    <visual name="l_upper_leg_visual">
      <origin rpy="-2.67797  1.57079 -1.10715" xyz="0 0 0"/>
      <geometry>
        <mesh filename="package://demonstrator6_description/meshes/visual/icub_l_thigh.dae" scale="1 1 1"/>
      </geometry>
    </visual>
  </link>
  <link name="l_lower_leg">
    <inertial>
      <mass value="10.264"/>
      <origin rpy="0 0 0" xyz="-0.1071   0.00182  0.00211"/>
      <inertia ixx="1000.01" ixy="-0.000185699" ixz="-6.3147e-05" iyy="1000.01" iyz="7.86e-07" izz="1000.01"/>
    </inertial>
    <collision name="l_lower_leg_collision">
      <origin rpy="-3.14159  0       1.5708" xyz="0 0 0"/>
      <geometry>
        <mesh filename="package://demonstrator6_description/meshes/collision/icub_simple_collision_l_shank.dae" scale="1 1 1"/>
      </geometry>
    </collision>
    <visual name="l_lower_leg_visual">
      <origin rpy="-3.14159  0       1.5708" xyz="0 0 0"/>
      <geometry>
        <mesh filename="package://demonstrator6_description/meshes/visual/icub_l_shank.dae" scale="1 1 1"/>
      </geometry>
    </visual>
  </link>
  <link name="l_ankle_1">
    <inertial>
      <mass value="100.746"/>
      <origin rpy="0 0 0" xyz="-0.0054   0.00163  0.0172"/>
      <inertia ixx="0.01" ixy="-7.081e-06" ixz="4.1421e-05" iyy="0.01" iyz="2.0817e-05" izz="0.01"/>
    </inertial>
    <collision name="l_ankle_1_collision">
      <origin rpy="1.5708 0     0" xyz="0 0 0"/>
      <geometry>
        <mesh filename="package://demonstrator6_description/meshes/collision/icub_simple_collision_l_ankle_1.dae" scale="1 1 1"/>
      </geometry>
    </collision>
    <visual name="l_ankle_1_visual">
      <origin rpy="1.5708 0     0" xyz="0 0 0"/>
      <geometry>
        <mesh filename="package://demonstrator6_description/meshes/visual/icub_l_ankle_1.dae" scale="1 1 1"/>
      </geometry>
    </visual>
  </link>
  <link name="l_ankle_2">
    <inertial>
      <mass value="100.2675"/>
      <origin rpy="0 0 0" xyz="0    0    0.037"/>
      <inertia ixx="0.01" ixy="0" ixz="0" iyy="0.01" iyz="0" izz="0.01"/>
    </inertial>
  </link>
  <link name="l_foot">
    <inertial>
      <mass value="1000.5935"/>
      <origin rpy="0 0 0" xyz="0.02406 -0.00061 -0.02841"/>
      <inertia ixx="1000.0" ixy="0.0" ixz="0.0" iyy="1000.0" iyz="0.0" izz="1000.0"/>
    </inertial>
    <collision name="l_foot_collision">
      <origin rpy="0 0 0" xyz="0.03  0   -0.01"/>
      <geometry>
        <box size="0.15 0.07 0.03"/>
      </geometry>
    </collision>
    <visual name="l_foot_visual">
      <origin rpy="-0.7854   1.57079 -0.7854" xyz="0     0    -0.037"/>
      <geometry>
        <mesh filename="package://demonstrator6_description/meshes/visual/icub_l_foot.dae" scale="1 1 1"/>
      </geometry>
    </visual>
  </link>
  <link name="r_hip_1">
    <inertial>
      <mass value="0.754"/>
      <origin rpy="0 0 0" xyz="0     -0.0782  0"/>
      <inertia ixx="0.01" ixy="0" ixz="0" iyy="0.01" iyz="0" izz="0.01"/>
    </inertial>
    <collision name="r_hip_1_collision">
      <origin rpy="1.76819 -1.57079  2.76109" xyz="0 0 0"/>
      <geometry>
        <mesh filename="package://demonstrator6_description/meshes/collision/icub_simple_collision_r_hip_1.dae" scale="1 1 1"/>
      </geometry>
    </collision>
    <visual name="r_hip_1_visual">
      <origin rpy="1.76819 -1.57079  2.76109" xyz="0 0 0"/>
      <geometry>
        <mesh filename="package://demonstrator6_description/meshes/visual/icub_r_hip_1.dae" scale="1 1 1"/>
      </geometry>
    </visual>
  </link>
  <link name="r_hip_2">
    <inertial>
      <mass value="0.526"/>
      <origin rpy="0 0 0" xyz="0      0      0.03045"/>
      <inertia ixx="0.01" ixy="0" ixz="0" iyy="0.01" iyz="0" izz="0.01"/>
    </inertial>
    <collision name="r_hip_2_collision">
      <origin rpy="-2.35627 -1.57079  2.35627" xyz="0 0 0"/>
      <geometry>
        <mesh filename="package://demonstrator6_description/meshes/collision/icub_simple_collision_r_hip_2.dae" scale="1 1 1"/>
      </geometry>
    </collision>
    <visual name="r_hip_2_visual">
      <origin rpy="-2.35627 -1.57079  2.35627" xyz="0 0 0"/>
      <geometry>
        <mesh filename="package://demonstrator6_description/meshes/visual/icub_r_hip_2.dae" scale="1 1 1"/>
      </geometry>
    </visual>
  </link>
  <link name="r_hip_3">
    <inertial>
      <mass value="0.1"/>
      <origin rpy="0 0 0" xyz="0 0 0"/>
      <inertia ixx="0.01" ixy="0" ixz="0" iyy="0.01" iyz="0" izz="0.01"/>
    </inertial>
  </link>
  <link name="r_upper_leg">
    <inertial>
      <mass value="20.175"/>
      <origin rpy="0 0 0" xyz="0.00144 -0.15942  0.00039"/>
      <inertia ixx="100.01" ixy="0" ixz="0" iyy="100.01" iyz="-2.71051e-20" izz="100.01"/>
    </inertial>
    <collision name="r_upper_leg_collision">
      <origin rpy="1.57087e+00 -1.57079e+00 -7.00000e-05" xyz="0 0 0"/>
      <geometry>
        <mesh filename="package://demonstrator6_description/meshes/collision/icub_simple_collision_r_thigh.dae" scale="1 1 1"/>
      </geometry>
    </collision>
    <visual name="r_upper_leg_visual">
      <origin rpy="1.57087e+00 -1.57079e+00 -7.00000e-05" xyz="0 0 0"/>
      <geometry>
        <mesh filename="package://demonstrator6_description/meshes/visual/icub_r_thigh.dae" scale="1 1 1"/>
      </geometry>
    </visual>
  </link>
  <link name="r_lower_leg">
    <inertial>
      <mass value="100.264"/>
      <origin rpy="0 0 0" xyz="-0.1071   0.00182 -0.00211"/>
      <inertia ixx="100.01" ixy="5.42101e-20" ixz="-5.42101e-20" iyy="100.01" iyz="8.47033e-22" izz="100.01"/>
    </inertial>
    <collision name="r_lower_leg_collision">
      <origin rpy="3.14159 0      1.5708" xyz="0 0 0"/>
      <geometry>
        <mesh filename="package://demonstrator6_description/meshes/collision/icub_simple_collision_r_shank.dae" scale="1 1 1"/>
      </geometry>
    </collision>
    <visual name="r_lower_leg_visual">
      <origin rpy="3.14159 0      1.5708" xyz="0 0 0"/>
      <geometry>
        <mesh filename="package://demonstrator6_description/meshes/visual/icub_r_shank.dae" scale="1 1 1"/>
      </geometry>
    </visual>
  </link>
  <link name="r_ankle_1">
    <inertial>
      <mass value="100.746"/>
      <origin rpy="0 0 0" xyz="-0.0054   0.00163 -0.0172"/>
      <inertia ixx="100.01" ixy="-1.69407e-21" ixz="1.35525e-20" iyy="100.01" iyz="3.38813e-21" izz="100.01"/>
    </inertial>
    <collision name="r_ankle_1_collision">
      <origin rpy="-1.5708  0      0" xyz="0 0 0"/>
      <geometry>
        <mesh filename="package://demonstrator6_description/meshes/collision/icub_simple_collision_r_ankle_1.dae" scale="1 1 1"/>
      </geometry>
    </collision>
    <visual name="r_ankle_1_visual">
      <origin rpy="-1.5708  0      0" xyz="0 0 0"/>
      <geometry>
        <mesh filename="package://demonstrator6_description/meshes/visual/icub_r_ankle_1.dae" scale="1 1 1"/>
      </geometry>
    </visual>
  </link>
  <link name="r_ankle_2">
    <inertial>
      <mass value="100.2675"/>
      <origin rpy="0 0 0" xyz="0    0    0.037"/>
      <inertia ixx="100.01" ixy="0" ixz="0" iyy="100.01" iyz="0" izz="100.01"/>
    </inertial>
  </link>
  <link name="r_foot">
    <inertial>
      <mass value="1000.5935"/>
      <origin rpy="0 0 0" xyz="0.02406  0.00061 -0.02841"/>
      <inertia ixx="1000.0" ixy="0.0" ixz="0.0" iyy="1000.0" iyz="0.0" izz="1000.0"/>
    </inertial>
    <collision name="r_foot_collision">
      <origin rpy="0 0 0" xyz="0.03  0   -0.01"/>
      <geometry>
        <box size="0.15 0.07 0.03"/>
      </geometry>
    </collision>
    <visual name="r_foot_visual">
      <origin rpy="-2.81983  1.57079  0.32176" xyz="0     0    -0.037"/>
      <geometry>
        <mesh filename="package://demonstrator6_description/meshes/visual/icub_r_foot.dae" scale="1 1 1"/>
      </geometry>
    </visual>
  </link>
  <link name="torso_1">
    <inertial>
      <mass value="0.1"/>
      <origin rpy="0 0 0" xyz="0 0 0"/>
      <inertia ixx="0.01" ixy="-4.263e-05" ixz="-3.889e-08" iyy="0.01" iyz="0" izz="0.01"/>
    </inertial>
    <collision name="torso_1_collision">
      <origin rpy="-1.5708  0      0" xyz="0 0 0"/>
      <geometry>
        <mesh filename="package://demonstrator6_description/meshes/collision/icub_simple_collision_lap_belt_1.dae" scale="1 1 1"/>
      </geometry>
    </collision>
    <visual name="torso_1_visual">
      <origin rpy="-1.5708  0      0" xyz="0 0 0"/>
      <geometry>
        <mesh filename="package://demonstrator6_description/meshes/visual/icub_lap_belt_1.dae" scale="1 1 1"/>
      </geometry>
    </visual>
  </link>
  <link name="torso_2">
    <inertial>
      <mass value="0.1"/>
      <origin rpy="0 0 0" xyz="0 0 0"/>
      <inertia ixx="0.01" ixy="-1.923e-06" ixz="5.095e-05" iyy="0.01" iyz="-3.849e-07" izz="0.01"/>
    </inertial>
  </link>
  <link name="chest">
    <inertial>
      <mass value="4.81"/>
      <origin rpy="0 0 0" xyz="0.00222 0.075   0"/>
      <inertia ixx="0.07472" ixy="-3.6e-06" ixz="-4.705e-05" iyy="0.08145" iyz="0.004567" izz="0.01306"/>
    </inertial>
    <collision name="chest_collision">
      <origin rpy="-1.10717 -1.57079  2.67798" xyz="-0.0055  0      0"/>
      <geometry>
        <mesh filename="package://demonstrator6_description/meshes/collision/icub_simple_collision_chest.dae" scale="1 1 1"/>
      </geometry>
    </collision>
    <visual name="chest_visual">
      <origin rpy="-1.10717 -1.57079  2.67798" xyz="-0.0055  0      0"/>
      <geometry>
        <mesh filename="package://demonstrator6_description/meshes/visual/icub_chest.dae" scale="1 1 1"/>
      </geometry>
    </visual>
  </link>
  <link name="l_shoulder_1">
    <inertial>
      <mass value="0.189"/>
      <origin rpy="0 0 0" xyz="0       0.0187  -0.00119"/>
      <inertia ixx="0.01" ixy="9e-09" ixz="0" iyy="0.01" iyz="-1.7e-08" izz="0.01"/>
    </inertial>
    <collision name="l_shoulder_1_collision">
      <origin rpy="-0.30106  1.57079 -1.87186" xyz="0       0.10928 -0.00521"/>
      <geometry>
        <mesh filename="package://demonstrator6_description/meshes/collision/icub_simple_collision_l_shoulder_1.dae" scale="1 1 1"/>
      </geometry>
    </collision>
    <visual name="l_shoulder_1_visual">
      <origin rpy="-0.30106  1.57079 -1.87186" xyz="0       0.10928 -0.00521"/>
      <geometry>
        <mesh filename="package://demonstrator6_description/meshes/visual/icub_l_shoulder_1.dae" scale="1 1 1"/>
      </geometry>
    </visual>
  </link>
  <link name="l_shoulder_2">
    <inertial>
      <mass value="0.179"/>
      <origin rpy="0 0 0" xyz="9.00e-05 -6.27e-03  1.66e-02"/>
      <inertia ixx="0.01" ixy="4.66e-07" ixz="3.65e-07" iyy="0.01" iyz="-2.0524e-05" izz="0.01"/>
    </inertial>
    <collision name="l_shoulder_2_collision">
      <origin rpy="-2.14033  1.57079 -0.56953" xyz="-0.00154 -0.00521  0"/>
      <geometry>
        <mesh filename="package://demonstrator6_description/meshes/collision/icub_simple_collision_l_shoulder_2.dae" scale="1 1 1"/>
      </geometry>
    </collision>
    <visual name="l_shoulder_2_visual">
      <origin rpy="-2.14033  1.57079 -0.56953" xyz="-0.00154 -0.00521  0"/>
      <geometry>
        <mesh filename="package://demonstrator6_description/meshes/visual/icub_l_shoulder_2.dae" scale="1 1 1"/>
      </geometry>
    </visual>
  </link>
  <link name="l_shoulder_3">
    <inertial>
      <mass value="0.156157"/>
      <origin rpy="0 0 0" xyz="5.590e-03 9.000e-05 5.013e-02"/>
      <inertia ixx="0.01" ixy="-5.662e-08" ixz="-4.3618e-06" iyy="0.01" iyz="-7.42844e-07" izz="0.01"/>
    </inertial>
  </link>
  <link name="l_upper_arm">
    <inertial>
      <mass value="0.727843"/>
      <origin rpy="0 0 0" xyz="-1.50e-04 -9.00e-05  2.98e-02"/>
      <inertia ixx="0.01" ixy="-1.08e-06" ixz="-2.29e-06" iyy="0.01" iyz="3.57e-06" izz="0.01"/>
    </inertial>
    <collision name="l_upper_arm_collision">
      <origin rpy="0     0    -1.309" xyz="-0.02043  0.00014 -0.068"/>
      <geometry>
        <mesh filename="package://demonstrator6_description/meshes/collision/icub_simple_collision_l_arm.dae" scale="1 1 1"/>
      </geometry>
    </collision>
    <visual name="l_upper_arm_visual">
      <origin rpy="0     0    -1.309" xyz="-0.02043  0.00014 -0.068"/>
      <geometry>
        <mesh filename="package://demonstrator6_description/meshes/visual/icub_l_arm.dae" scale="1 1 1"/>
      </geometry>
    </visual>
  </link>
  <link name="l_elbow_1">
    <inertial>
      <mass value="0.1"/>
      <origin rpy="0 0 0" xyz="-0.0013   0.00371 -0.00105"/>
      <inertia ixx="0.01" ixy="-5.15e-07" ixz="-4.08e-07" iyy="0.01" iyz="-3.71e-07" izz="0.01"/>
    </inertial>
  </link>
  <link name="l_forearm">
    <inertial>
      <mass value="0.525"/>
      <origin rpy="0 0 0" xyz="0.00034 0.066   0.00476"/>
      <inertia ixx="0.01" ixy="4.337e-06" ixz="2.39e-07" iyy="0.01" iyz="1.9381e-05" izz="0.01"/>
    </inertial>
    <collision name="l_forearm_collision">
      <origin rpy="-2.66395  1.57079 -1.09315" xyz="-0.00014  0       0.02043"/>
      <geometry>
        <mesh filename="package://demonstrator6_description/meshes/collision/icub_simple_collision_l_forearm.dae" scale="1 1 1"/>
      </geometry>
    </collision>
    <visual name="l_forearm_visual">
      <origin rpy="-2.66395  1.57079 -1.09315" xyz="-0.00014  0       0.02043"/>
      <geometry>
        <mesh filename="package://demonstrator6_description/meshes/visual/icub_l_forearm.dae" scale="1 1 1"/>
      </geometry>
    </visual>
  </link>
  <link name="l_wrist_1">
    <inertial>
      <mass value="0.1"/>
      <origin rpy="0 0 0" xyz="0 0 0"/>
      <inertia ixx="0.01" ixy="0" ixz="0" iyy="0.01" iyz="0" izz="0.01"/>
    </inertial>
  </link>
  <link name="l_hand">
    <inertial>
      <mass value="0.213"/>
      <origin rpy="0 0 0" xyz="0.07023 -0.00805 -0.007"/>
      <inertia ixx="1.01" ixy="1.278e-05" ixz="4.823e-06" iyy="1.01" iyz="-1.8188e-05" izz="1.01"/>
    </inertial>
    <collision name="l_hand_collision">
      <origin rpy="0 0 0" xyz="0       0.02043 -0.00014"/>
      <geometry>
        <mesh filename="package://demonstrator6_description/meshes/collision/icub_simple_collision_l_hand.dae" scale="1 1 1"/>
      </geometry>
    </collision>
    <visual name="l_hand_visual">
      <origin rpy="0 0 0" xyz="0       0.02043 -0.00014"/>
      <geometry>
        <mesh filename="package://demonstrator6_description/meshes/visual/icub_l_hand.dae" scale="1 1 1"/>
      </geometry>
    </visual>
  </link>
  <link name="neck_1">
    <inertial>
      <mass value="0.1"/>
      <origin rpy="0 0 0" xyz="0 0 0"/>
      <inertia ixx="0.01" ixy="0" ixz="0" iyy="0.01" iyz="0" izz="0.01"/>
    </inertial>
    <collision name="neck_1_collision">
      <origin rpy="3.14159 -1.57079  1.5708" xyz="0      0     -0.0055"/>
      <geometry>
        <mesh filename="package://demonstrator6_description/meshes/collision/icub_simple_collision_neck_1.dae" scale="1 1 1"/>
      </geometry>
    </collision>
    <visual name="neck_1_visual">
      <origin rpy="3.14159 -1.57079  1.5708" xyz="0      0     -0.0055"/>
      <geometry>
        <mesh filename="package://demonstrator6_description/meshes/visual/icub_neck_1.dae" scale="1 1 1"/>
      </geometry>
    </visual>
  </link>
  <link name="neck_2">
    <inertial>
      <mass value="0.1"/>
      <origin rpy="0 0 0" xyz="0 0 0"/>
      <inertia ixx="0.01" ixy="0" ixz="0" iyy="0.01" iyz="0" izz="0.01"/>
    </inertial>
    <collision name="neck_2_collision">
      <origin rpy="-3.14157 -1.57079 -1.57082" xyz="0     0.0055 0.0235"/>
      <geometry>
        <mesh filename="package://demonstrator6_description/meshes/collision/icub_simple_collision_neck_2.dae" scale="1 1 1"/>
      </geometry>
    </collision>
    <visual name="neck_2_visual">
      <origin rpy="-3.14157 -1.57079 -1.57082" xyz="0     0.0055 0.0235"/>
      <geometry>
        <mesh filename="package://demonstrator6_description/meshes/visual/icub_neck_2.dae" scale="1 1 1"/>
      </geometry>
    </visual>
  </link>
  <link name="head">
    <inertial>
      <mass value="3"/>
      <origin rpy="0 0 0" xyz="0.0185 -0.1108  0"/>
      <inertia ixx="0.01" ixy="0" ixz="0" iyy="0.01" iyz="0" izz="0.01"/>
    </inertial>
    <collision name="head_collision">
      <origin rpy="-1.32582  1.57079 -2.89662" xyz="0.00449 -0.0235   0"/>
      <geometry>
        <mesh filename="package://demonstrator6_description/meshes/collision/icub_simple_collision_head.dae" scale="1 1 1"/>
      </geometry>
    </collision>
    <visual name="head_visual">
      <origin rpy="-1.32582  1.57079 -2.89662" xyz="0.00449 -0.0235   0"/>
      <geometry>
        <mesh filename="package://demonstrator6_description/meshes/visual/icub_head.dae" scale="1 1 1"/>
      </geometry>
    </visual>
  </link>
  <link name="eye_frame">
    <inertial>
      <mass value="0.5"/>
      <origin rpy="0 0 0" xyz="0 0 0"/>
      <inertia ixx="0.01" ixy="0" ixz="0" iyy="0.01" iyz="0" izz="0.01"/>
    </inertial>
    <collision name="eye_frame_collision">
      <origin rpy="0 0 0" xyz="0 0 0"/>
      <geometry>
        <sphere radius=".005"/>
      </geometry>
    </collision>
    <visual name="eye_frame_visual">
      <origin rpy="0 0 0" xyz="0 0 0"/>
      <geometry>
        <sphere radius=".005"/>
      </geometry>
    </visual>
  </link>
  <link name="left_eye">
    <inertial>
      <mass value="0.5"/>
      <origin rpy="0 0 0" xyz="0 0 0"/>
      <inertia ixx="0.01" ixy="0" ixz="0" iyy="0.01" iyz="0" izz="0.01"/>
    </inertial>
    <collision name="left_eye_collision">
      <origin rpy="0 0 0" xyz="0 0 0"/>
      <geometry>
        <sphere radius=".0245"/>
      </geometry>
    </collision>
    <collision name="left_pupil_collision">
      <origin rpy="1.5707 0     1.5707" xyz="-0.0245  0      0"/>
      <geometry>
        <cylinder length=".008" radius=".008"/>
      </geometry>
    </collision>
    <visual name="left_eye_visual">
      <origin rpy="0 0 0" xyz="0 0 0"/>
      <geometry>
        <sphere radius=".0245"/>
      </geometry>
    </visual>
    <visual name="left_pupil_visual">
      <origin rpy="1.5707 0     1.5707" xyz="-0.0245  0      0"/>
      <geometry>
        <cylinder length=".008" radius=".008"/>
      </geometry>
    </visual>
  </link>
  <link name="right_eye">
    <inertial>
      <mass value="0.5"/>
      <origin rpy="0 0 0" xyz="0 0 0"/>
      <inertia ixx="0.01" ixy="0" ixz="0" iyy="0.01" iyz="0" izz="0.01"/>
    </inertial>
    <collision name="right_eye_collision">
      <origin rpy="0 0 0" xyz="0 0 0"/>
      <geometry>
        <sphere radius=".0245"/>
      </geometry>
    </collision>
    <collision name="right_pupil_collision">
      <origin rpy="1.5707 0     1.5707" xyz="-0.0245  0      0"/>
      <geometry>
        <cylinder length=".008" radius=".008"/>
      </geometry>
    </collision>
    <visual name="right_eye_visual">
      <origin rpy="0 0 0" xyz="0 0 0"/>
      <geometry>
        <sphere radius=".0245"/>
      </geometry>
    </visual>
    <visual name="right_pupil_visual">
      <origin rpy="1.5707 0     1.5707" xyz="-0.0245  0      0"/>
      <geometry>
        <cylinder length=".008" radius=".008"/>
      </geometry>
    </visual>
  </link>
  <link name="r_shoulder_1">
    <inertial>
      <mass value="0.189"/>
      <origin rpy="0 0 0" xyz="0      0.0187  0.00119"/>
      <inertia ixx="0.01" ixy="2.1e-08" ixz="-1e-09" iyy="0.01" iyz="4.22e-06" izz="0.01"/>
    </inertial>
    <collision name="r_shoulder_1_collision">
      <origin rpy="3.06003  1.57079 -1.65235" xyz="0      0.10928 0.00521"/>
      <geometry>
        <mesh filename="package://demonstrator6_description/meshes/collision/icub_simple_collision_r_shoulder_1.dae" scale="1 1 1"/>
      </geometry>
    </collision>
    <visual name="r_shoulder_1_visual">
      <origin rpy="3.06003  1.57079 -1.65235" xyz="0      0.10928 0.00521"/>
      <geometry>
        <mesh filename="package://demonstrator6_description/meshes/visual/icub_r_shoulder_1.dae" scale="1 1 1"/>
      </geometry>
    </visual>
  </link>
  <link name="r_shoulder_2">
    <inertial>
      <mass value="0.179"/>
      <origin rpy="0 0 0" xyz="-9.00e-05 -6.27e-03 -1.66e-02"/>
      <inertia ixx="0.01" ixy="-4.53e-07" ixz="2.03e-07" iyy="0.01" iyz="2.07e-05" izz="0.01"/>
    </inertial>
    <collision name="r_shoulder_2_collision">
      <origin rpy="-1.00125 -1.57079  2.57205" xyz="-0.00154 -0.00521  0"/>
      <geometry>
        <mesh filename="package://demonstrator6_description/meshes/collision/icub_simple_collision_r_shoulder_2.dae" scale="1 1 1"/>
      </geometry>
    </collision>
    <visual name="r_shoulder_2_visual">
      <origin rpy="-1.00125 -1.57079  2.57205" xyz="-0.00154 -0.00521  0"/>
      <geometry>
        <mesh filename="package://demonstrator6_description/meshes/visual/icub_r_shoulder_2.dae" scale="1 1 1"/>
      </geometry>
    </visual>
  </link>
  <link name="r_shoulder_3">
    <inertial>
      <mass value="0.155"/>
      <origin rpy="0 0 0" xyz="5.530e-03 -2.000e-05  4.939e-02"/>
      <inertia ixx="0.01" ixy="3.56977e-07" ixz="-3.95372e-06" iyy="0.01" iyz="-6.5128e-06" izz="0.01"/>
    </inertial>
  </link>
  <link name="r_upper_arm">
    <inertial>
      <mass value="0.729"/>
      <origin rpy="0 0 0" xyz="-1.500e-04  8.000e-05  2.988e-02"/>
      <inertia ixx="0.01" ixy="-1.08e-06" ixz="-2.29e-06" iyy="0.01" iyz="3.57e-06" izz="0.01"/>
    </inertial>
    <collision name="r_upper_arm_collision">
      <origin rpy="-3.14159  0       1.309" xyz="-0.02043 -0.00014 -0.068"/>
      <geometry>
        <mesh filename="package://demonstrator6_description/meshes/collision/icub_simple_collision_r_arm.dae" scale="1 1 1"/>
      </geometry>
    </collision>
    <visual name="r_upper_arm_visual">
      <origin rpy="-3.14159  0       1.309" xyz="-0.02043 -0.00014 -0.068"/>
      <geometry>
        <mesh filename="package://demonstrator6_description/meshes/visual/icub_r_arm.dae" scale="1 1 1"/>
      </geometry>
    </visual>
  </link>
  <link name="r_elbow_1">
    <inertial>
      <mass value="0.1"/>
      <origin rpy="0 0 0" xyz="0.0013  -0.00371  0.00105"/>
      <inertia ixx="0.01" ixy="-5.02e-07" ixz="-3.99e-07" iyy="0.01" iyz="-3.71e-07" izz="0.01"/>
    </inertial>
  </link>
  <link name="r_forearm">
    <inertial>
      <mass value="0.525"/>
      <origin rpy="0 0 0" xyz="-0.00034 -0.066   -0.00476"/>
      <inertia ixx="0.01" ixy="5.66e-06" ixz="1.4e-06" iyy="0.01" iyz="1.82e-05" izz="0.01"/>
    </inertial>
    <collision name="r_forearm_collision">
      <origin rpy="-1.74165  1.57079 -0.17086" xyz="0.00014  0      -0.02043"/>
      <geometry>
        <mesh filename="package://demonstrator6_description/meshes/collision/icub_simple_collision_r_forearm.dae" scale="1 1 1"/>
      </geometry>
    </collision>
    <visual name="r_forearm_visual">
      <origin rpy="-1.74165  1.57079 -0.17086" xyz="0.00014  0      -0.02043"/>
      <geometry>
        <mesh filename="package://demonstrator6_description/meshes/visual/icub_r_forearm.dae" scale="1 1 1"/>
      </geometry>
    </visual>
  </link>
  <link name="r_wrist_1">
    <inertial>
      <mass value="0.1"/>
      <origin rpy="0 0 0" xyz="0 0 0"/>
      <inertia ixx="0.01" ixy="0" ixz="0" iyy="0.01" iyz="0" izz="0.01"/>
    </inertial>
  </link>
  <link name="r_hand">
    <inertial>
      <mass value="0.213"/>
      <origin rpy="0 0 0" xyz="0.07023 -0.00805  0.007"/>
      <inertia ixx="0.01" ixy="1.26e-05" ixz="-6.08e-06" iyy="0.01" iyz="1.76e-05" izz="0.01"/>
    </inertial>
    <collision name="r_hand_collision">
      <origin rpy="0       0      -3.14159" xyz="0      0.02043 0.00014"/>
      <geometry>
        <mesh filename="package://demonstrator6_description/meshes/collision/icub_simple_collision_r_hand.dae" scale="1 1 1"/>
      </geometry>
    </collision>
    <visual name="r_hand_visual">
      <origin rpy="0       0      -3.14159" xyz="0      0.02043 0.00014"/>
      <geometry>
        <mesh filename="package://demonstrator6_description/meshes/visual/icub_r_hand.dae" scale="1 1 1"/>
      </geometry>
    </visual>
  </link>
  <plugin name="ROSController_iCub" filename="libcontroller_ros_gazebo_icub.so"/>
  <plugin name="InitiCub" filename="libicub_initialization.so"/>
  <plugin name='ros_control' filename='libgazebo_ros_control.so'>
    <robotNamespace>/icub</robotNamespace>
  </plugin>
</robot>
